Workbook
Name Slicer_brand_name: #N/A
Name Slicer_product_category: #N/A

Sheet Cleaned_data
A1: product_name | B1: brand_name | C1: rating | D1: rating_count | E1: marked_price | F1: discounted_price | G1: sizes | H1: product_category | I1: product_id | J1: revenue | K1: discount %
A2: Pure Georgette Bandhani Saree | B2: Mitera | C2: 3.6 | D2: 5 | E2: 6727 | F2: 1681 | G2: Onesize | H2: sarees | I2: 17141476 | J2: =D2*F2 -> 8405 | K2: =((Table4[[#This Row],[marked_price]]-Table4[[#This Row],[discounted_price]])/Table4[[#This Row],[marked_price]])*100 -> 75.011149
A3: Men Accessory Gift Set | B3: WildHorn | C3: 4.5 | D3: 80 | E3: 2999 | F3: 1049 | G3: Onesize | H3: accessory-gift-set | I3: 1410357 | J3: =D3*F3 -> 83920 | K3: =((Table4[[#This Row],[marked_price]]-Table4[[#This Row],[discounted_price]])/Table4[[#This Row],[marked_price]])*100 -> 65.021674
A4: Self-Design Thermal Set | B4: Kanvin | C4: 4.6 | D4: 42 | E4: 1598 | F4: 1278 | G4: S,M,L,XL,XXL | H4: thermal-set | I4: 2223155 | J4: =D4*F4 -> 53676 | K4: =((Table4[[#This Row],[marked_price]]-Table4[[#This Row],[discounted_price]])/Table4[[#This Row],[marked_price]])*100 -> 20.025031
A5: Men Slim Fit T-shirt | B5: Jack & Jones | C5: 3.7 | D5: 7 | E5: 1299 | F5: 649 | G5: S,M,L,XL,XXL | H5: tshirts | I5: 15430520 | J5: =D5*F5 -> 4543 | K5: =((Table4[[#This Row],[marked_price]]-Table4[[#This Row],[discounted_price]])/Table4[[#This Row],[marked_price]])*100 -> 50.038491
A6: Outdoor Rapid-Dry Jacket | B6: HRX by Hrithik Roshan | C6: 4.4 | D6: 186 | E6: 2799 | F6: 1679 | G6: XS,S,M,L,XL | H6: jackets | I6: 11953112 | J6: =D6*F6 -> 312294 | K6: =((Table4[[#This Row],[marked_price]]-Table4[[#This Row],[discounted_price]])/Table4[[#This Row],[marked_price]])*100 -> 40.014291
A7: Floral Maxi Dress | B7: Nayo | C7: 4 | D7: 7 | E7: 1999 | F7: 799 | G7: S,M,L,XL,XXL | H7: dresses | I7: 17634118 | J7: =D7*F7 -> 5593 | K7: =((Table4[[#This Row],[marked_price]]-Table4[[#This Row],[discounted_price]])/Table4[[#This Row],[marked_price]])*100 -> 60.030015
A8: Women Ribbed Fitted Top | B8: DressBerry | C8: 4.2 | D8: 252 | E8: 999 | F8: 399 | G8: XS,S,M,L,XL | H8: tops | I8: 11003624 | J8: =D8*F8 -> 100548 | K8: =((Table4[[#This Row],[marked_price]]-Table4[[#This Row],[discounted_price]])/Table4[[#This Row],[marked_price]])*100 -> 60.06006
A9: Men Gold-Toned Brooch | B9: Alvaro Castagnino | C9: 4.9 | D9: 10 | E9: 999 | F9: 399 | G9: Onesize | H9: brooch | I9: 17426638 | J9: =D9*F9 -> 3990 | K9: =((Table4[[#This Row],[marked_price]]-Table4[[#This Row],[discounted_price]])/Table4[[#This Row],[marked_price]])*100 -> 60.06006
A10: Printed Lounge T-shirt | B10: ETC | C10: 4.3 | D10: 52 | E10: 499 | F10: 324 | G10: S,M,L,XL | H10: lounge-tshirts | I10: 12442110 | J10: =D10*F10 -> 16848 | K10: =((Table4[[#This Row],[marked_price]]-Table4[[#This Row],[discounted_price]])/Table4[[#This Row],[marked_price]])*100 -> 35.07014
A11: Men Solid Sliders | B11: Power | C11: 3.9 | D11: 34 | E11: 746 | F11: 671 | G11: UK6,UK7,UK8,UK9,UK10,UK11 | H11: flip-flops | I11: 12453854 | J11: =D11*F11 -> 22814 | K11: =((Table4[[#This Row],[marked_price]]-Table4[[#This Row],[discounted_price]])/Table4[[#This Row],[marked_price]])*100 -> 10.053619
A12: Women Skinny Fit Jeans | B12: Mast & Harbour | C12: 4 | D12: 105 | E12: 1799 | F12: 809 | G12: 26,28,30,32,34,36 | H12: jeans | I12: 12310178 | J12: =D12*F12 -> 84945 | K12: =((Table4[[#This Row],[marked_price]]-Table4[[#This Row],[discounted_price]])/Table4[[#This Row],[marked_price]])*100 -> 55.030573
A13: Unisex Round Sunglasses | B13: WROGN | C13: 4.1 | D13: 338 | E13: 2899 | F13: 1884 | G13: M | H13: sunglasses | I13: 2385219 | J13: =D13*F13 -> 636792 | K13: =((Table4[[#This Row],[marked_price]]-Table4[[#This Row],[discounted_price]])/Table4[[#This Row],[marked_price]])*100 -> 35.012073
... A369: Men Analogue Watch | B369: TIMESMITH | C369: 3.9 | D369: 7 | E369: 2499 | F369: 399 | G369: Onesize | H369: watches | I369: 11135920 | J369: =D369*F369 -> 2793 | K369: =((Table4[[#This Row],[marked_price]]-Table4[[#This Row],[discounted_price]])/Table4[[#This Row],[marked_price]])*100 -> 84.033613
A370: Men Leather Formal Belt | B370: United Colors of Benetton | C370: 3.4 | D370: 7 | E370: 2999 | F370: 899 | G370: 34 | H370: belts | I370: 8488829 | J370: =D370*F370 -> 6293 | K370: =((Table4[[#This Row],[marked_price]]-Table4[[#This Row],[discounted_price]])/Table4[[#This Row],[marked_price]])*100 -> 70.023341
A371: Cone Shade Armed Sconces | B371: Homesake | C371: 4.3 | D371: 21 | E371: 3300 | F371: 1199 | G371: Onesize | H371: wall-lamps | I371: 9246303 | J371: =D371*F371 -> 25179 | K371: =((Table4[[#This Row],[marked_price]]-Table4[[#This Row],[discounted_price]])/Table4[[#This Row],[marked_price]])*100 -> 63.666667
A372: Women Slim Fit Regular Trousers | B372: FORCLAZ By Decathlon | C372: 5 | D372: 6 | E372: 2999 | F372: 2579 | G372: 26,28,30,32,34,36 | H372: trousers | I372: 13168086 | J372: =D372*F372 -> 15474 | K372: =((Table4[[#This Row],[marked_price]]-Table4[[#This Row],[discounted_price]])/Table4[[#This Row],[marked_price]])*100 -> 14.004668
A373: Embroidered High-Low Top | B373: Mayra | C373: 3.1 | D373: 36 | E373: 1095 | F373: 459 | G373: S,M,L,XL | H373: tops | I373: 11091590 | J373: =D373*F373 -> 16524 | K373: =((Table4[[#This Row],[marked_price]]-Table4[[#This Row],[discounted_price]])/Table4[[#This Row],[marked_price]])*100 -> 58.082192
A374: Printed Kurta with Palazzos | B374: FABRIC FITOOR | C374: 4.5 | D374: 15 | E374: 4599 | F374: 1057 | G374: S,M,L,XL,XXL,3XL | H374: kurta-sets | I374: 12103850 | J374: =D374*F374 -> 15855 | K374: =((Table4[[#This Row],[marked_price]]-Table4[[#This Row],[discounted_price]])/Table4[[#This Row],[marked_price]])*100 -> 77.016743
A375: Women Yoke Design Kurta with Trousers With Dupatta | B375: Varanga | C375: 1 | D375: 2 | E375: 4999 | F375: 1699 | G375: S,M,L,XL,XXL | H375: kurta-sets | I375: 13983922 | J375: =D375*F375 -> 3398 | K375: =((Table4[[#This Row],[marked_price]]-Table4[[#This Row],[discounted_price]])/Table4[[#This Row],[marked_price]])*100 -> 66.013203
A376: Men Typography Printed T-shirt | B376: HERE&NOW | C376: 3.8 | D376: 5 | E376: 949 | F376: 284 | G376: S,M,L,XL | H376: tshirts | I376: 16260732 | J376: =D376*F376 -> 1420 | K376: =((Table4[[#This Row],[marked_price]]-Table4[[#This Row],[discounted_price]])/Table4[[#This Row],[marked_price]])*100 -> 70.073762
A377: Unisex Anti Theft Backpack | B377: F Gear | C377: 4.5 | D377: 191 | E377: 4995 | F377: 1898 | G377: Onesize | H377: backpacks | I377: 4385679 | J377: =D377*F377 -> 362518 | K377: =((Table4[[#This Row],[marked_price]]-Table4[[#This Row],[discounted_price]])/Table4[[#This Row],[marked_price]])*100 -> 62.002002
A378: Men Solid Kurta with Pyjamas | B378: VASTRAMAY | C378: 4.4 | D378: 43 | E378: 4499 | F378: 2249 | G378: S,M,L,XL,XXL,3XL | H378: kurta-sets | I378: 4369942 | J378: =D378*F378 -> 96707 | K378: =((Table4[[#This Row],[marked_price]]-Table4[[#This Row],[discounted_price]])/Table4[[#This Row],[marked_price]])*100 -> 50.011114
A379: Girls Embroidered Kurta with Palazzos With Dupatta | B379: Biba | C379: 4.1 | D379: 7 | E379: 3299 | F379: 1649 | G379: 9Y,11Y,13Y,15Y | H379: kurta-sets | I379: 14847260 | J379: =D379*F379 -> 11543 | K379: =((Table4[[#This Row],[marked_price]]-Table4[[#This Row],[discounted_price]])/Table4[[#This Row],[marked_price]])*100 -> 50.015156
A380: PU Structured Sling Bag | B380: Exotic | C380: 4.7 | D380: 9 | E380: 2599 | F380: 1074 | G380: S | H380: handbags | I380: 17394202 | J380: =D380*F380 -> 9666 | K380: =((Table4[[#This Row],[marked_price]]-Table4[[#This Row],[discounted_price]])/Table4[[#This Row],[marked_price]])*100 -> 58.676414
A381: AD-Studded Mangalsutra Set | B381: Brandsoon | C381: 5 | D381: 2 | E381: 2528 | F381: 353 | G381: Onesize | H381: mangalsutra | I381: 17403044 | J381: =D381*F381 -> 706 | K381: =((Table4[[#This Row],[marked_price]]-Table4[[#This Row],[discounted_price]])/Table4[[#This Row],[marked_price]])*100 -> 86.036392
A382: Women Embroidered Rozana Kurta | B382: House of Pataudi | C382: 4.2 | D382: 5 | E382: 3199 | F382: 1919 | G382: XS,S,M,L,XL,XXL | H382: kurtas | I382: 13721048 | J382: =D382*F382 -> 9595 | K382: =((Table4[[#This Row],[marked_price]]-Table4[[#This Row],[discounted_price]])/Table4[[#This Row],[marked_price]])*100 -> 40.012504
... A717: Scoop Neck Fitted Top | B717: Miaz Lifestyle | C717: 3.5 | D717: 88 | E717: 999 | F717: 589 | G717: XS,S,M,L,XL,XXL | H717: tops | I717: 15112544 | J717: =D717*F717 -> 51832 | K717: =((Table4[[#This Row],[marked_price]]-Table4[[#This Row],[discounted_price]])/Table4[[#This Row],[marked_price]])*100 -> 41.041041
A718: Slim Fit Casual Shirt | B718: Louis Philippe Jeans | C718: 3.3 | D718: 3 | E718: 2049 | F718: 1229 | G718: 44 | H718: shirts | I718: 14225978 | J718: =D718*F718 -> 3687 | K718: =((Table4[[#This Row],[marked_price]]-Table4[[#This Row],[discounted_price]])/Table4[[#This Row],[marked_price]])*100 -> 40.019522
A719: Girls Layered A-Line Dress | B719: pspeaches | C719: 4.4 | D719: 54 | E719: 1499 | F719: 524 | G719: 2-3Y,3-4Y,4-5Y,5-6Y,6-7Y,7-8Y,8-9Y,9-10Y,10-11Y,11-12Y | H719: dresses | I719: 13882872 | J719: =D719*F719 -> 28296 | K719: =((Table4[[#This Row],[marked_price]]-Table4[[#This Row],[discounted_price]])/Table4[[#This Row],[marked_price]])*100 -> 65.043362
A720: Women Printed Kurta with Palazzos | B720: Moda Rapido | C720: 3.9 | D720: 8 | E720: 4399 | F720: 1099 | G720: XS,S,M,L,XL,XXL | H720: kurta-sets | I720: 14430866 | J720: =D720*F720 -> 8792 | K720: =((Table4[[#This Row],[marked_price]]-Table4[[#This Row],[discounted_price]])/Table4[[#This Row],[marked_price]])*100 -> 75.017049
A721: Suede Block Mules with Buckles | B721: VALIOSAA | C721: 3.5 | D721: 6 | E721: 2499 | F721: 1474 | G721: EURO35,EURO36,EURO37,EURO38,EURO39,EURO40 | H721: heels | I721: 15777288 | J721: =D721*F721 -> 8844 | K721: =((Table4[[#This Row],[marked_price]]-Table4[[#This Row],[discounted_price]])/Table4[[#This Row],[marked_price]])*100 -> 41.016407
A722: Women Floral Embroidered Kurta | B722: KALINI | C722: 2.8 | D722: 5 | E722: 1249 | F722: 399 | G722: M,L,XL,XXL,3XL | H722: kurtas | I722: 17227692 | J722: =D722*F722 -> 1995 | K722: =((Table4[[#This Row],[marked_price]]-Table4[[#This Row],[discounted_price]])/Table4[[#This Row],[marked_price]])*100 -> 68.054444
A723: Women Solid Block Heels | B723: Padvesh | C723: 3.4 | D723: 5 | E723: 1299 | F723: 649 | G723: EURO38,EURO39,EURO40,EURO41,EURO42 | H723: heels | I723: 12826644 | J723: =D723*F723 -> 3245 | K723: =((Table4[[#This Row],[marked_price]]-Table4[[#This Row],[discounted_price]])/Table4[[#This Row],[marked_price]])*100 -> 50.038491
A724: Women Cotton Solid Pullover | B724: MANGO | C724: 4.2 | D724: 9 | E724: 2990 | F724: 1794 | G724: XS,S,M,L | H724: sweaters | I724: 15721508 | J724: =D724*F724 -> 16146 | K724: =((Table4[[#This Row],[marked_price]]-Table4[[#This Row],[discounted_price]])/Table4[[#This Row],[marked_price]])*100 -> 40
A725: Women High Waist Tummy & Thigh Control Seamless Shapewear | B725: SECRETS BY ZEROKAATA | C725: 3.8 | D725: 138 | E725: 1000 | F725: 820 | G725: M,L,XL | H725: shapewear | I725: 13549778 | J725: =D725*F725 -> 113160 | K725: =((Table4[[#This Row],[marked_price]]-Table4[[#This Row],[discounted_price]])/Table4[[#This Row],[marked_price]])*100 -> 18
A726: Geometric Regular Top | B726: Trend Arrest | C726: 4.2 | D726: 9 | E726: 1299 | F726: 480 | G726: XS,S,M,L,XL | H726: tops | I726: 16247900 | J726: =D726*F726 -> 4320 | K726: =((Table4[[#This Row],[marked_price]]-Table4[[#This Row],[discounted_price]])/Table4[[#This Row],[marked_price]])*100 -> 63.048499
A727: Satin Wrap Dress | B727: NEUDIS | C727: 3.6 | D727: 5 | E727: 2199 | F727: 791 | G727: XS,S,M,L,XL | H727: dresses | I727: 16923146 | J727: =D727*F727 -> 3955 | K727: =((Table4[[#This Row],[marked_price]]-Table4[[#This Row],[discounted_price]])/Table4[[#This Row],[marked_price]])*100 -> 64.029104
A728: Men Skinny Fit Jeans | B728: Allen Solly | C728: 3.5 | D728: 2 | E728: 2799 | F728: 1931 | G728: 30,32,34,36,38 | H728: jeans | I728: 14843430 | J728: =D728*F728 -> 3862 | K728: =((Table4[[#This Row],[marked_price]]-Table4[[#This Row],[discounted_price]])/Table4[[#This Row],[marked_price]])*100 -> 31.011075
A729: Men Solid T-shirt | B729: Moda Rapido | C729: 3.3 | D729: 6 | E729: 999 | F729: 519 | G729: S,M,L,XL | H729: tshirts | I729: 15822046 | J729: =D729*F729 -> 3114 | K729: =((Table4[[#This Row],[marked_price]]-Table4[[#This Row],[discounted_price]])/Table4[[#This Row],[marked_price]])*100 -> 48.048048
...

Sheet brand_pivot
C2: BRAND PIVOT
C4: Row Labels | D4: Average of marked_price | E4: Average of discounted_price | G4: Row Labels | H4: Average of rating | J4: Row Labels | K4: Sum of rating_count | M4: Row Labels | N4: Sum of revenue | P4: Row Labels | Q4: Count of product_category
C5: ADIDAS | D5: 2844.4545 | E5: 2265.3636 | G5: ADIDAS | H5: 4.3636364 | J5: ADIDAS | K5: 759 | M5: ADIDAS | N5: 897081 | P5: ADIDAS | Q5: 11
C6: Allen Solly | D6: 2370.7143 | E6: 1776.7 | G6: Allen Solly | H6: 4.3285714 | J6: Allen Solly | K6: 2833 | M6: Allen Solly | N6: 3905605 | P6: Allen Solly | Q6: 70
C7: Nike | D7: 2895 | E7: 2796.2308 | G7: Nike | H7: 4.4307692 | J7: Nike | K7: 306 | M7: Nike | N7: 766322 | P7: Nike | Q7: 13
C8: Puma | D8: 2991.9825 | E8: 1819.5263 | G8: Puma | H8: 4.2640351 | J8: Puma | K8: 3326 | M8: Puma | N8: 5564869 | P8: Puma | Q8: 114
C9: Grand Total | D9: 2769.0385 | E9: 1889.7356 | G9: Grand Total | H9: 4.3014423 | J9: Grand Total | K9: 7224 | M9: Grand Total | N9: 11133877 | P9: Grand Total | Q9: 208

Sheet brand_dashboard
C2: BRAND DASHBOARD

Sheet product_pivot
B2: PRODUCT PIVOT
B5: Row Labels | C5: Avg of discounted_price | D5: Aveg of marked_price | F5: Row Labels | G5: Sum of rating_count | I5: Row Labels | J5: Count of brand_name
B6: action-figures-and-play-set | C6: 591 | D6: 799 | F6: action-figures-and-play-set | G6: 9 | I6: action-figures-and-play-set | J6: 1
B7: baby-care-products | C7: 344 | D7: 349 | F7: baby-care-products | G7: 932 | I7: baby-care-products | J7: 3
B8: track-pants | C8: 1099.2143 | D8: 1953 | F8: track-pants | G8: 17942 | I8: track-pants | J8: 252
B9: tshirts | C9: 677.15254 | D9: 1207.0473 | F9: tshirts | G9: 94149 | I9: tshirts | J9: 1121
B10: Grand Total | C10: 753.60421 | D10: 1341.3958 | F10: Grand Total | G10: 113032 | I10: Grand Total | J10: 1377

Sheet product_dashboard
C3: PRODUCT DASHBOARD

Sheet Overall_Dashboard
E3: Overall Dashboard
G6: Total products | H6: Total brands | I6: Total categories | J6: Total people | K6: Total rating
E7: Raw data | G7: =COUNTA([1]V1!$A$2:$A$24325) -> 24324 | H7: =COUNTA([1]V1!$B$1:$B$24325) -> 24325 | I7: =COUNTA([1]V2!$I$5:$I$21605) -> 21601 | J7: =SUM([1]V1!$D$1:$D$21605) -> 1247767 | K7: =AVERAGE([1]V1!$C$2:$C$24325) -> 2.1832264
E9: Cleaned data | G9: =COUNTA(Cleaned_data!A2:A11439) -> 11438 | H9: =COUNTA(_xlfn.UNIQUE(Cleaned_data!B2:B11439)) -> 1458 | I9: =COUNTA(_xlfn.UNIQUE(Cleaned_data!H2:H11439)) -> 245 | J9: =SUM(Cleaned_data!D2:D11439) -> 1404665 | K9: =AVERAGE(Cleaned_data!C2:C11439) -> 4.1597744

Sheet LinkedIn_Dashboard
A1: MYNTRA PRODUCT DATA ANALYSIS
A2: Cleaned dataset insights • 11,438 unique products • Top 5 performance analysis
A3: TOTAL PRODUCTS | E3: TOTAL BRANDS | I3: CATEGORIES | M3: RATING VOLUME | Q3: AVG. RATING | U3: ENGAGEMENT VALUE
A4: =Overall_Dashboard!G9 -> 11438 | E4: =Overall_Dashboard!H9 -> 1458 | I4: =Overall_Dashboard!I9 -> 245 | M4: =Overall_Dashboard!J9 -> 1404665 | Q4: =Overall_Dashboard!K9 -> 4.1597744 | U4: =SUM(Cleaned_data!J2:J11439) -> 1281237476
A6: Brand & Category Performance
A37: TOP BRAND Roadster leads with 80,847 ratings. | I37: TOP CATEGORY Perfume & Body Mist dominates with 125,303 ratings. | Q37: RATING LEADER MCaffeine scores 4.61, highest among the Top 5 brands.
A40: Created by Madhavareddy Erugula | Excel • Data Cleaning • Pivot Tables • Dashboarding
A45: Brand | B45: Avg Marked Price | C45: Avg Discounted Price | D45: Brand | E45: Avg Rating | F45: Brand | G45: Rating Count | H45: Brand | I45: Engagement Value | J45: Brand | K45: Product Count | L45: Category | M45: Avg Marked Price | N45: Avg Discounted Price | O45: Category | P45: Rating Count | Q45: Category | R45: Product Count
A46: Roadster | B46: 1768.1947 | C46: 782.11062 | D46: Roadster | E46: 4.1309735 | F46: Roadster | G46: 80847 | H46: Roadster | I46: 59111098 | J46: Roadster | K46: 452 | L46: Perfume And Body Mist | M46: 2723.8 | N46: 2382.75 | O46: Perfume And Body Mist | P46: 125303 | Q46: Perfume And Body Mist | R46: 100
A47: DressBerry | B47: 1896.4356 | C47: 803.83556 | D47: DressBerry | E47: 4.2102222 | F47: DressBerry | G47: 71240 | H47: DressBerry | I47: 48535395 | J47: DressBerry | K47: 225 | L47: T-Shirts | M47: 1207.0473 | N47: 677.15254 | O47: T-Shirts | P47: 94149 | Q47: T-Shirts | R47: 1121
A48: Plum | B48: 665.71429 | C48: 535.5 | D48: Plum | E48: 4.4 | F48: Plum | G48: 65603 | H48: Plum | I48: 56575241 | J48: Plum | K48: 14 | L48: Tops | M48: 1423.6266 | N48: 740.82143 | O48: Tops | P48: 59387 | Q48: Tops | R48: 616
A49: Lakme | B49: 516.91667 | C49: 471.29167 | D49: Lakme | E49: 4.3791667 | F49: Lakme | G49: 51360 | H49: Lakme | I49: 32333287 | J49: Lakme | K49: 24 | L49: Kurtas | M49: 2168.9098 | N49: 946.23333 | O49: Kurtas | P49: 52705 | Q49: Kurtas | R49: 510
A50: MCaffeine | B50: 716.2 | C50: 625.1 | D50: MCaffeine | E50: 4.61 | F50: MCaffeine | G50: 42789 | H50: MCaffeine | I50: 38870147 | J50: MCaffeine | K50: 10 | L50: Dresses | M50: 2482.7915 | N50: 1249.0352 | O50: Dresses | P50: 51634 | Q50: Dresses | R50: 710
